Workbook

Sheet README
A1: TITLE | B1: THE STOCK ELEPHANT -- Part III: Seven-Actor SFC Toy Model
A3: PURPOSE | B3: This spreadsheet implements a Stock-Flow Consistent (SFC) balance sheet model for seven actors in the international dollar circuit. Every inter-actor flow is enforced by formula. The SFC_CHECK sheet verifies that all accounting identities hold across all years.
A5: YEAR MAPPING | B5: Y0=2016 (baseline), Y1=2017, Y2=2018, Y3=2019, Y4=2020 (COVID), Y5=2021, Y6=2022 (basis trade surge), Y7=2023 (QDLP reopens), Y8=2024, Y9=2025, Y10+=Stress scenario. NOTE: In the published article, only Y0..Y10+ labels are used. No calendar dates appear in the publication.
A7: NAMING CONVENTIONS | B7: AmeriCo = reserve currency issuer (US analog). JapanCo = surplus accumulator (China analog). JapCBCo = JapanCo central bank sub-account. JapY = JapanCo domestic currency (CNY analog). JapInv = JapanCo outward investment projects (BRI analog). CommodityCo = commodity-exporting sovereign (Gulf/EM analog, generic). GlobalBankCo = large international bank. RepoCo = repo desk / FICC member. HedgeCo = basis trade vehicle (Cayman-registered). FedCo = AmeriCo central bank / absorber of last resort.
A9: UNITS | B9: All values in stylized $B (billions). Toy model -- ratios matter, not absolute scale. Real-world order-of-magnitude calibration noted in ASSUMPTIONS sheet.
A11: COLOR CODING | B11: BLUE TEXT = hardcoded input (change these for scenarios). BLACK TEXT = formula (do not hardcode). GREEN TEXT = cross-sheet reference. GREEN BACKGROUND = asset rows. ORANGE BACKGROUND = liability rows. PURPLE BACKGROUND = derivative / off-balance-sheet rows. YELLOW BACKGROUND = equity / net worth rows. BLUE BACKGROUND = fractional measure rows. RED BACKGROUND = stress scenario rows.
A13: SFC IDENTITIES | B13: The following identities must hold at every year column. They are verified in SFC_CHECK sheet. Any red cell in SFC_CHECK indicates a model error.
A14: Identity 1 | B14: JapanCo deposit at GlobalBankCo = GlobalBankCo liability to JapanCo
A15: Identity 2 | B15: CommodityCo deposit at GlobalBankCo = GlobalBankCo liability to CommodityCo
A16: Identity 3 | B16: GlobalBankCo repo to RepoCo = RepoCo repo payable to GlobalBankCo
A17: Identity 4 | B17: RepoCo repo to HedgeCo = HedgeCo repo payable to RepoCo
A18: Identity 5 | B18: HedgeCo long cash Treasury = Treasury held via repo chain (= RepoCo repo to HedgeCo)
... A28: PUBLICATION NOTE | B28: Internal working document. Publication version uses Y0..Y10+ labels only, removes CommodityCo name, removes JapCBCo/JapY/JapInv labels, and presents fractional measure formulas without estimated values. Editorial decision on what to publish made at end of drafting.

Sheet ASSUMPTIONS
A1: ASSUMPTIONS -- All hardcoded inputs (blue). Change here; formulas flow through.
A2: Account / Line Item | B2: Notes / Source | C2: Y0 | D2: Y1 | E2: Y2 | F2: Y3 | G2: Y4 | H2: Y5 | I2: Y6 | J2: Y7 | K2: Y8 | L2: Y9 | M2: Y10+ Stress
A3: AMERICО ASSUMPTIONS
A4: Productive capital K_real ($B) | B4: Stylized. Real-world US fixed capital ~$60T; toy model ratios matter not scale. | C4: 300 | D4: 310 | E4: 325 | F4: 340 | G4: 330 | H4: 345 | I4: 365 | J4: 380 | K4: 400 | L4: 415 | M4: 400
A5: GDP (Y_productive, $B) | B5: Toy model GDP. FISIM-adjusted -- financial sector value-add excluded. | C5: 280 | D5: 287 | E5: 294 | F5: 302 | G5: 288 | H5: 300 | I5: 308 | J5: 315 | K5: 320 | L5: 318 | M5: 300
A6: CA deficit per year ($B) | B6: Real-world US CA deficit: ~$1T/yr by 2024. Toy model scaled. | C6: 40 | D6: 45 | E6: 50 | F6: 55 | G6: 60 | H6: 65 | I6: 80 | J6: 90 | K6: 100 | L6: 110 | M6: 120
A7: NIIP Y0 starting value ($B) | B7: Only Y0 is input. Subsequent years formula: prior year + CA deficit. | C7: -80 | D7: 0 | E7: 0 | F7: 0 | G7: 0 | H7: 0 | I7: 0 | J7: 0 | K7: 0 | L7: 0 | M7: 0
A8: Official reserve liabilities Y0 ($B) | B8: Real-world: $7.5T official reserves globally. Toy model scaled. | C8: 200 | D8: 0 | E8: 0 | F8: 0 | G8: 0 | H8: 0 | I8: 0 | J8: 0 | K8: 0 | L8: 0 | M8: 0
A9: Reserve growth rate (% per year) | B9: Flat since 2015 peak. Real-world PBOC reserves ~$3.1T, stable. | C9: 0.015 | D9: 0.015 | E9: 0.01 | F9: 0.005 | G9: 0 | H9: -0.005 | I9: -0.003 | J9: 0.002 | K9: 0.005 | L9: 0.003 | M9: 0
A11: JAPANCO ASSUMPTIONS
A12: CA surplus per year ($B) | B12: Real-world China CA surplus: record ~$1.2T in 2024 (Bloomberg Jan 2026). | C12: 200 | D12: 210 | E12: 350 | F12: 420 | G12: 310 | H12: 350 | I12: 420 | J12: 250 | K12: 500 | L12: 600 | M12: 550
A13: PBOC (JapCBCo) reserve accumulation rate (% of surplus) | B13: Most surplus NOT going to official reserves since 2015. Setser routing gap. | C13: 0.05 | D13: 0.05 | E13: 0.05 | F13: 0.03 | G13: 0.02 | H13: 0.02 | I13: 0.01 | J13: 0.02 | K13: 0.01 | L13: 0.01 | M13: 0.01
A14: GlobalBankCo deposit rate (% of routing gap) | B14: State rerouting channel. BIS LBS code G proxy (loans+deposits, inseparable). | C14: 0.08 | D14: 0.09 | E14: 0.1 | F14: 0.1 | G14: 0.12 | H14: 0.13 | I14: 0.18 | J14: 0.15 | K14: 0.15 | L14: 0.14 | M14: 0.12
A15: JapInv project lending per year ($B) | B15: JapanCo outward project lending (BRI analog). | C15: 8 | D15: 10 | E15: 15 | F15: 18 | G15: 15 | H15: 15 | I15: 14 | J15: 14 | K15: 14 | L15: 12 | M15: 12
A16: Private channel open? (1=yes, 0=no) | B16: QDLP: halted Jul 2015 (pre-Y0), reinstated Apr 2018 (Y2), halted again ~Y4, QDLP expansion Sep 2023 (Y7). | C16: 0 | D16: 0 | E16: 1 | F16: 1 | G16: 0 | H16: 0 | I16: 0 | J16: 1 | K16: 1 | L16: 1 | M16: 1
A17: Private channel flow (% of surplus, if open) | B17: QDII quota: $159.7B. Small relative to total routing gap. | C17: 0 | D17: 0 | E17: 0.05 | F17: 0.05 | G17: 0 | H17: 0 | I17: 0 | J17: 0.03 | K17: 0.04 | L17: 0.05 | M17: 0.05
A19: COMMODITYCO ASSUMPTIONS
A20: Commodity receivables Y0 ($B) | B20: Oil/gas/minerals export receivables. Volatile. | C20: 60 | D20: 0 | E20: 0 | F20: 0 | G20: 0 | H20: 0 | I20: 0 | J20: 0 | K20: 0 | L20: 0 | M20: 0
A21: Commodity price change (% per year) | B21: Stylized commodity cycle. Y4/2020 COVID shock. Y10+ stress: -50%. | C21: 0.05 | D21: -0.1 | E21: 0.05 | F21: 0.1 | G21: -0.45 | H21: 0.3 | I21: 0.2 | J21: 0.05 | K21: 0.1 | L21: -0.05 | M21: -0.5
A22: GlobalBankCo deposit Y0 ($B) | B22: Dollar liquid buffer. First withdrawal target under stress. | C22: 45 | D22: 0 | E22: 0 | F22: 0 | G22: 0 | H22: 0 | I22: 0 | J22: 0 | K22: 0 | L22: 0 | M22: 0
A23: Deposit growth rate (% per year, ex-stress) | B23: Y10+ stress: CLC breach forces -45% withdrawal. | C23: 0.03 | D23: 0.04 | E23: 0.04 | F23: 0.03 | G23: -0.06 | H23: 0.08 | I23: 0.06 | J23: 0.05 | K23: 0.05 | L23: 0.02 | M23: -0.45
A24: Direct Treasury Y0 ($B) | B24: TIC-visible sovereign Treasury holdings. | C24: 20 | D24: 0 | E24: 0 | F24: 0 | G24: 0 | H24: 0 | I24: 0 | J24: 0 | K24: 0 | L24: 0 | M24: 0
A25: Treasury growth rate (% per year, ex-stress) | B25: Y10+ stress: forced sale alongside deposit withdrawal. | C25: 0.02 | D25: 0.03 | E25: 0.03 | F25: 0.02 | G25: -0.04 | H25: 0.06 | I25: 0.05 | J25: 0.04 | K25: 0.04 | L25: 0.02 | M25: -0.47
A26: Gold reserves Y0 ($B) | C26: 25 | D26: 0 | E26: 0 | F26: 0 | G26: 0 | H26: 0 | I26: 0 | J26: 0 | K26: 0 | L26: 0 | M26: 0
A27: Gold growth rate (% per year, normal)
A28: Gold liquidation fraction (stress year Y10+) | C28: 0 | D28: 0 | E28: 0 | F28: 0 | G28: 0 | H28: 0 | I28: 0 | J28: 0 | K28: 0 | L28: 0 | M28: 0.6
A29: Gold proceeds routed to GBC deposit (% of proceeds) | C29: 0 | D29: 0 | E29: 0 | F29: 0 | G29: 0 | H29: 0 | I29: 0 | J29: 0 | K29: 0 | L29: 0 | M29: 0.8
A30: GLOBALBANKCO ASSUMPTIONS
A31: Other loans and advances Y0 ($B) | C31: 25 | D31: 0 | E31: 0 | F31: 0 | G31: 0 | H31: 0 | I31: 0 | J31: 0 | K31: 0 | L31: 0 | M31: 0
A32: Other loans growth rate | C32: 0.03 | D32: 0.04 | E32: 0.04 | F32: -0.05 | G32: 0.05 | H32: 0.04 | I32: 0.04 | J32: 0.03 | K32: 0.02 | L32: -0.1 | M32: -0.15
A33: SLR minimum (%) | B33: US GSIB SLR minimum 5%. Perera (Feb 2026): SLR reform Nov 2025 changes denominator. | C33: 0.05 | D33: 0.05 | E33: 0.05 | F33: 0.05 | G33: 0.05 | H33: 0.05 | I33: 0.05 | J33: 0.05 | K33: 0.05 | L33: 0.05 | M33: 0.05
A34: SLR constraint threshold (constrained if below, %)
A35: Repo spread (GlobalBankCo to RepoCo, bps) | B35: Stylized. Repo spread widens in stress. | C35: 5 | D35: 5 | E35: 5 | F35: 5 | G35: 8 | H35: 8 | I35: 6 | J35: 6 | K35: 6 | L35: 6 | M35: 6
A37: REPOCO ASSUMPTIONS
A38: Repo spread (RepoCo to HedgeCo, bps)
A39: FICC novation fraction (% of repo book off-balance-sheet) | B39: Rising: basis trade growth pushes more volume through FICC CCP. Barth-Beltran: $1.4T invisible = ~76% of total by end-Y8. | C39: 0.25 | D39: 0.3 | E39: 0.35 | F39: 0.4 | G39: 0.5 | H39: 0.55 | I39: 0.7 | J39: 0.72 | K39: 0.75 | L39: 0.76 | M39: 0.76
A41: HEDGECO ASSUMPTIONS | C41: 1.3 | D41: 1.3 | E41: 1.3 | F41: 1.3 | G41: 1.3 | H41: 1.3 | I41: 1.3 | J41: 1.3 | K41: 1.3 | L41: 1.3 | M41: 1.3
A42: Futures short notional as multiple of cash long
A43: HedgeCo equity ($B) | B43: Equity base. Leverage = gross exposure / equity. | C43: 10 | D43: 10 | E43: 10 | F43: 10 | G43: 10 | H43: 10 | I43: 10 | J43: 10 | K43: 10 | L43: 10 | M43: 10
A45: FEDCO ASSUMPTIONS
...

Sheet AmeriCo
A1: AmeriCo | Reserve Issuer | Treasury Issuer | Productive Base
A2: Account / Line Item | B2: Notes / Source | C2: Y0 | D2: Y1 | E2: Y2 | F2: Y3 | G2: Y4 | H2: Y5 | I2: Y6 | J2: Y7 | K2: Y8 | L2: Y9 | M2: Y10+ Stress
A3: ASSETS
A4: Productive capital K_real ($B) | B4: FISIM-adjusted. κ divergence theorem: κ_paper rises faster than κ_real as FISIM contamination grows. | C4: =ASSUMPTIONS!C4 -> 300 | D4: =ASSUMPTIONS!D4 -> 310 | E4: =ASSUMPTIONS!E4 -> 325 | F4: =ASSUMPTIONS!F4 -> 340 | G4: =ASSUMPTIONS!G4 -> 330 | H4: =ASSUMPTIONS!H4 -> 345 | I4: =ASSUMPTIONS!I4 -> 365 | J4: =ASSUMPTIONS!J4 -> 380 | ... M4: =ASSUMPTIONS!M4 -> 400
A5: Outward FDI ($B) | B5: Channel One legacy: AmeriCo lends long via FDI while borrowing short via reserve accumulation (Kindleberger 1966). | C5: 200 | D5: =C5*(1+0.02) -> 204 | E5: =D5*(1+0.02) -> 208.08 | F5: =E5*(1+0.02) -> 212.2416 | G5: =F5*(1+0.02) -> 216.48643 | H5: =G5*(1+0.02) -> 220.81616 | I5: =H5*(1+0.02) -> 225.23248 | J5: =I5*(1+0.02) -> 229.73713 | K5: =J5*(1+0.02) -> 234.33188 | ... M5: =L5*(1+0.02) -> 243.79888
A6: Other foreign claims ($B) | C6: 80 | D6: =C6*1.02 -> 81.6 | E6: =D6*1.02 -> 83.232 | F6: =E6*1.02 -> 84.89664 | G6: =F6*1.02 -> 86.594573 | H6: =G6*1.02 -> 88.326464 | I6: =H6*1.02 -> 90.092994 | J6: =I6*1.02 -> 91.894853 | K6: =J6*1.02 -> 93.73275 | ... M6: =L6*1.02 -> 97.519554
A7: TOTAL ASSETS | C7: =SUM(C4:C6) -> 580 | D7: =SUM(D4:D6) -> 595.6 | E7: =SUM(E4:E6) -> 616.312 | F7: =SUM(F4:F6) -> 637.13824 | G7: =SUM(G4:G6) -> 633.081 | H7: =SUM(H4:H6) -> 654.14262 | I7: =SUM(I4:I6) -> 680.32548 | J7: =SUM(J4:J6) -> 701.63199 | ... M7: =SUM(M4:M6) -> 741.31844
A9: LIABILITIES
A10: Official reserve liabilities ($B) | B10: Foreign CB holdings. Flat since 2015 peak -- routing gap begins here. | C10: =ASSUMPTIONS!C8 -> 200 | D10: =C10*(1+ASSUMPTIONS!C9) -> 203 | E10: =D10*(1+ASSUMPTIONS!C9) -> 206.045 | F10: =E10*(1+ASSUMPTIONS!C9) -> 209.13567 | G10: =F10*(1+ASSUMPTIONS!C9) -> 212.27271 | H10: =G10*(1+ASSUMPTIONS!C9) -> 215.4568 | I10: =H10*(1+ASSUMPTIONS!C9) -> 218.68865 | J10: =I10*(1+ASSUMPTIONS!C9) -> 221.96898 | K10: =J10*(1+ASSUMPTIONS!C9) -> 225.29852 | L10: =K10*(1+ASSUMPTIONS!C9) -> 228.678 | M10: =L10*(1+ASSUMPTIONS!C9) -> 232.10817
A11: Private foreign Treasury (TIC-visible, $B) | B11: Barth-Beltran TIC-visible portion: $423B end-Y8. TVR = this / total basis trade. | C11: =RepoCo!C4 -> 75 | D11: =RepoCo!D4 -> 88.0285 | E11: =RepoCo!E4 -> 109.4745 | F11: =RepoCo!F4 -> 132.43668 | G11: =RepoCo!G4 -> 133.70977 | H11: =RepoCo!H4 -> 149.32109 | I11: =RepoCo!I4 -> 140.83522 | J11: =RepoCo!J4 -> 171.40964 | ... M11: =RepoCo!M4 -> 258.37419
A12: Private foreign Treasury (TIC-INVISIBLE, $B) | B12: Basis trade exposure invisible via FICC novation. Barth-Beltran: $1,427B invisible end-Y8. | C12: =RepoCo!C13 -> 25 | D12: =RepoCo!D13 -> 37.7265 | E12: =RepoCo!E13 -> 58.947805 | F12: =RepoCo!F13 -> 88.291119 | G12: =RepoCo!G13 -> 133.70977 | H12: =RepoCo!H13 -> 182.50356 | I12: =RepoCo!I13 -> 328.61551 | J12: =RepoCo!J13 -> 440.76765 | ... M12: =RepoCo!M13 -> 818.18494
A13: Other foreign dollar claims ($B) | C13: 200 | D13: =C13*1.02 -> 204 | E13: =D13*1.02 -> 208.08 | F13: =E13*1.02 -> 212.2416 | G13: =F13*1.02 -> 216.48643 | H13: =G13*1.02 -> 220.81616 | I13: =H13*1.02 -> 225.23248 | J13: =I13*1.02 -> 229.73713 | K13: =J13*1.02 -> 234.33188 | ... M13: =L13*1.02 -> 243.79888
A14: TOTAL LIABILITIES | C14: =SUM(C10:C13) -> 500 | D14: =SUM(D10:D13) -> 532.755 | E14: =SUM(E10:E13) -> 582.5473 | F14: =SUM(F10:F13) -> 642.10507 | G14: =SUM(G10:G13) -> 696.17868 | H14: =SUM(H10:H13) -> 768.09761 | I14: =SUM(I10:I13) -> 913.37187 | J14: =SUM(J10:J13) -> 1063.8834 | ... M14: =SUM(M10:M13) -> 1552.4662
A16: NET INTERNATIONAL INVESTMENT POSITION (NIIP)
A17: NIIP = Total Assets - Total Liabilities ($B) | B17: Real-world: US NIIP = -$26.5T end-2024. Toy model scaled ratios. | C17: =C7-C14 -> 80 | D17: =D7-D14 -> 62.845 | E17: =E7-E14 -> 33.7647 | F17: =F7-F14 -> -4.966833 | G17: =G7-G14 -> -63.097674 | H17: =H7-H14 -> -113.95498 | I17: =I7-I14 -> -233.04639 | J17: =J7-J14 -> -362.25141 | ... M17: =M7-M14 -> -811.14775
A19: FLOWS
A20: CA deficit per year ($B) | B20: Each year's deficit = net new claims issued on AmeriCo. Stock accumulates without ceiling. | C20: =ASSUMPTIONS!C7 -> -80 | D20: =ASSUMPTIONS!D7 -> 0 | E20: =ASSUMPTIONS!E7 -> 0 | F20: =ASSUMPTIONS!F7 -> 0 | G20: =ASSUMPTIONS!G7 -> 0 | H20: =ASSUMPTIONS!H7 -> 0 | I20: =ASSUMPTIONS!I7 -> 0 | J20: =ASSUMPTIONS!J7 -> 0 | ... M20: =ASSUMPTIONS!M7 -> 0
A22: FRACTIONAL MEASURES
A23: κ_paper = K_total / Y_productive | B23: Rising. FISIM contamination means κ_real diverges lower. Core κ divergence theorem claim. | C23: =(C7-C11-C12)/ASSUMPTIONS!C5 -> 1.7142857 | D23: =(D7-D11-D12)/ASSUMPTIONS!D5 -> 1.6370906 | E23: =(E7-E11-E12)/ASSUMPTIONS!E5 -> 1.5234344 | F23: =(F7-F11-F12)/ASSUMPTIONS!F5 -> 1.3788425 | G23: =(G7-G11-G12)/ASSUMPTIONS!G5 -> 1.2696579 | H23: =(H7-H11-H12)/ASSUMPTIONS!H5 -> 1.0743933 | I23: =(I7-I11-I12)/ASSUMPTIONS!I5 -> 0.68465826 | J23: =(J7-J11-J12)/ASSUMPTIONS!J5 -> 0.28398318 | ... M23: =(M7-M11-M12)/ASSUMPTIONS!M5 -> -1.117469
A24: NIIP / GDP | B24: Interest burden at 4%: ~$300B/yr on official reserves alone by Y8. | C24: =C17/ASSUMPTIONS!C5 -> 0.28571429 | D24: =D17/ASSUMPTIONS!D5 -> 0.21897213 | E24: =E17/ASSUMPTIONS!E5 -> 0.11484592 | F24: =F17/ASSUMPTIONS!F5 -> -0.016446467 | G24: =G17/ASSUMPTIONS!G5 -> -0.21908914 | H24: =H17/ASSUMPTIONS!H5 -> -0.37984994 | I24: =I17/ASSUMPTIONS!I5 -> -0.75664413 | J24: =J17/ASSUMPTIONS!J5 -> -1.1500045 | ... M24: =M17/ASSUMPTIONS!M5 -> -2.7038258
A25: TVR = TIC-visible / (TIC-visible + TIC-invisible) | B25: Barth-Beltran: TVR = $423B / $1,850B = 22.9% end-Y8. Structural gauge failure. | C25: =IF((C11+C12)=0,"-",C11/(C11+C12)) -> 0.75 | D25: =IF((D11+D12)=0,"-",D11/(D11+D12)) -> 0.7 | E25: =IF((E11+E12)=0,"-",E11/(E11+E12)) -> 0.65 | F25: =IF((F11+F12)=0,"-",F11/(F11+F12)) -> 0.6 | G25: =IF((G11+G12)=0,"-",G11/(G11+G12)) -> 0.5 | H25: =IF((H11+H12)=0,"-",H11/(H11+H12)) -> 0.45 | I25: =IF((I11+I12)=0,"-",I11/(I11+I12)) -> 0.3 | J25: =IF((J11+J12)=0,"-",J11/(J11+J12)) -> 0.28 | ... M25: =IF((M11+M12)=0,"-",M11/(M11+M12)) -> 0.24

Sheet GovCo
A1: GovCo | AmeriCo Treasury & Finance Ministry | Sovereign Debt Issuer
A2: Account / Line Item | B2: Notes | C2: Y0 | D2: Y1 | E2: Y2 | F2: Y3 | G2: Y4 | H2: Y5 | I2: Y6 | J2: Y7 | K2: Y8 | L2: Y9 | M2: Y10+
A3: ASSETS
A4: Tax & fee revenue ($B, annual flow) | B4: ASSUMPTIONS r55 | C4: =ASSUMPTIONS!C55 -> 260 | D4: =ASSUMPTIONS!D55 -> 260 | E4: =ASSUMPTIONS!E55 -> 260 | F4: =ASSUMPTIONS!F55 -> 260 | G4: =ASSUMPTIONS!G55 -> 260 | H4: =ASSUMPTIONS!H55 -> 260 | I4: =ASSUMPTIONS!I55 -> 260 | J4: =ASSUMPTIONS!J55 -> 260 | ... M4: =ASSUMPTIONS!M55 -> 260
A5: Other government assets ($B) | B5: Reserves, land, enterprise stakes | C5: 80 | D5: 80 | E5: 80 | F5: 80 | G5: 80 | H5: 80 | I5: 80 | J5: 80 | K5: 80 | L5: 80 | M5: 80
A6: TOTAL ASSETS | C6: =SUM(C4:C5) -> 340 | D6: =SUM(D4:D5) -> 340 | E6: =SUM(E4:E5) -> 340 | F6: =SUM(F4:F5) -> 340 | G6: =SUM(G4:G5) -> 340 | H6: =SUM(H4:H5) -> 340 | I6: =SUM(I4:I5) -> 340 | J6: =SUM(J4:J5) -> 340 | ... M6: =SUM(M4:M5) -> 340
A8: LIABILITIES
A9: GovCo bonds held by FedCo ($B) [SFC: = FedCo Treasury holdings] | B9: FedCo!Treasury r4 | C9: =FedCo!C4 -> 64 | D9: =FedCo!D4 -> 79 | E9: =FedCo!E4 -> 94 | F9: =FedCo!F4 -> 114 | G9: =FedCo!G4 -> 194 | H9: =FedCo!H4 -> 186 | I9: =FedCo!I4 -> 166 | J9: =FedCo!J4 -> 141 | ... M9: =FedCo!M4 -> 163
A10: Foreign private holdings via basis trade chain ($B) [= GlobalBankCo repo book = TIC-vis + TIC-invis combined] | B10: GlobalBankCo total repo book (TIC-vis + TIC-invis = same bonds) | C10: =GlobalBankCo!C4 -> 100 | D10: =GlobalBankCo!D4 -> 125.755 | E10: =GlobalBankCo!E4 -> 168.4223 | F10: =GlobalBankCo!F4 -> 220.7278 | G10: =GlobalBankCo!G4 -> 267.41954 | H10: =GlobalBankCo!H4 -> 331.82465 | I10: =GlobalBankCo!I4 -> 469.45073 | J10: =GlobalBankCo!J4 -> 612.17729 | ... M10: =GlobalBankCo!M4 -> 1076.5591
A11: Official reserve liabilities ($B) [= AmeriCo r10 = foreign central bank Treasury holdings] | B11: AmeriCo official reserve liabilities (foreign CB holdings) | C11: =AmeriCo!C10 -> 200 | D11: =AmeriCo!D10 -> 203 | E11: =AmeriCo!E10 -> 206.045 | F11: =AmeriCo!F10 -> 209.13567 | G11: =AmeriCo!G10 -> 212.27271 | H11: =AmeriCo!H10 -> 215.4568 | I11: =AmeriCo!I10 -> 218.68865 | J11: =AmeriCo!J10 -> 221.96898 | ... M11: =AmeriCo!M10 -> 232.10817
A12: GovCo bonds held domestic ($B) | B12: Residual = total - FedCo - foreign | C12: =ASSUMPTIONS!C52-C9-C10-C11 -> 16 | D12: =(C9+C10+C11+C12)+C19-D9-D10-D11 -> 27.445 | E12: =(D9+D10+D11+D12)+D19-E9-E10-E11 -> 21.9327 | F12: =(E9+E10+E11+E12)+E19-F9-F10-F11 -> 3.944527 | G12: =(F9+F10+F11+F12)+F19-G9-G10-G11 -> -66.268246 | H12: =(G9+G10+G11+G12)+G19-H9-H10-H11 -> -63.945128 | I12: =(H9+H10+H11+H12)+H19-I9-I10-I11 -> -120.50611 | J12: =(I9+I10+I11+I12)+I19-J9-J10-J11 -> -174.73954 | K12: =(J9+J10+J11+J12)+J19-K9-K10-K11 -> -280.99791 | ... M12: =(L9+L10+L11+L12)+L19-M9-M10-M11 -> -455.10888
A13: TOTAL LIABILITIES (GovCo bonds outstanding, $B) | C13: =SUM(C9:C12) -> 380 | D13: =SUM(D9:D12) -> 435.2 | E13: =SUM(E9:E12) -> 490.4 | F13: =SUM(F9:F12) -> 547.808 | G13: =SUM(G9:G12) -> 607.424 | H13: =SUM(H9:H12) -> 669.33632 | I13: =SUM(I9:I12) -> 733.63328 | J13: =SUM(J9:J12) -> 800.40673 | ... M13: =SUM(M9:M12) -> 1016.5584
A15: FISCAL FLOWS
A16: Tax revenue ($B) | C16: =ASSUMPTIONS!C55 -> 260 | D16: =ASSUMPTIONS!D55 -> 260 | E16: =ASSUMPTIONS!E55 -> 260 | F16: =ASSUMPTIONS!F55 -> 260 | G16: =ASSUMPTIONS!G55 -> 260 | H16: =ASSUMPTIONS!H55 -> 260 | I16: =ASSUMPTIONS!I55 -> 260 | J16: =ASSUMPTIONS!J55 -> 260 | ... M16: =ASSUMPTIONS!M55 -> 260
A17: Government spending ($B) | C17: =ASSUMPTIONS!C56 -> 300 | D17: =ASSUMPTIONS!D56 -> 300 | E17: =ASSUMPTIONS!E56 -> 300 | F17: =ASSUMPTIONS!F56 -> 300 | G17: =ASSUMPTIONS!G56 -> 300 | H17: =ASSUMPTIONS!H56 -> 300 | I17: =ASSUMPTIONS!I56 -> 300 | J17: =ASSUMPTIONS!J56 -> 300 | ... M17: =ASSUMPTIONS!M56 -> 300
A18: Interest on outstanding bonds ($B) | B18: Rate times total bonds outstanding prior year | C18: =ASSUMPTIONS!C54*ASSUMPTIONS!C52 -> 15.2 | D18: =ASSUMPTIONS!D54*C13 -> 15.2 | E18: =ASSUMPTIONS!E54*D13 -> 17.408 | F18: =ASSUMPTIONS!F54*E13 -> 19.616 | G18: =ASSUMPTIONS!G54*F13 -> 21.91232 | H18: =ASSUMPTIONS!H54*G13 -> 24.29696 | I18: =ASSUMPTIONS!I54*H13 -> 26.773453 | J18: =ASSUMPTIONS!J54*I13 -> 29.345331 | K18: =ASSUMPTIONS!K54*J13 -> 32.016269 | ... M18: =ASSUMPTIONS!M54*L13 -> 37.670733
A19: Fiscal deficit ($B) = spending + interest - revenue | C19: =C17+C18-C16 -> 55.2 | D19: =D17+D18-D16 -> 55.2 | E19: =E17+E18-E16 -> 57.408 | F19: =F17+F18-F16 -> 59.616 | G19: =G17+G18-G16 -> 61.91232 | H19: =H17+H18-H16 -> 64.29696 | I19: =I17+I18-I16 -> 66.773453 | J19: =J17+J18-J16 -> 69.345331 | ... M19: =M17+M18-M16 -> 77.670733
A21: FRACTIONAL MEASURES
A22: Debt / GDP | C22: =IF(ASSUMPTIONS!C5=0,"-",C13/ASSUMPTIONS!C5) -> 1.3571429 | D22: =IF(ASSUMPTIONS!C5=0,"-",D13/ASSUMPTIONS!C5) -> 1.5542857 | E22: =IF(ASSUMPTIONS!C5=0,"-",E13/ASSUMPTIONS!C5) -> 1.7514286 | F22: =IF(ASSUMPTIONS!C5=0,"-",F13/ASSUMPTIONS!C5) -> 1.9564571 | G22: =IF(ASSUMPTIONS!C5=0,"-",G13/ASSUMPTIONS!C5) -> 2.1693714 | H22: =IF(ASSUMPTIONS!C5=0,"-",H13/ASSUMPTIONS!C5) -> 2.3904869 | I22: =IF(ASSUMPTIONS!C5=0,"-",I13/ASSUMPTIONS!C5) -> 2.6201189 | J22: =IF(ASSUMPTIONS!C5=0,"-",J13/ASSUMPTIONS!C5) -> 2.8585955 | K22: =IF(ASSUMPTIONS!C5=0,"-",K13/ASSUMPTIONS!C5) -> 3.1062574 | L22: =IF(ASSUMPTIONS!C5=0,"-",L13/ASSUMPTIONS!C5) -> 3.3634583 | M22: =IF(ASSUMPTIONS!C5=0,"-",M13/ASSUMPTIONS!C5) -> 3.6305658
A23: Foreign-held share of GovCo bonds (visible + invisible) | C23: =IF(C13=0,"-",(C10+C11)/C13) -> 0.78947368 | D23: =IF(D13=0,"-",(D10+D11)/D13) -> 0.75541131 | E23: =IF(E13=0,"-",(E10+E11)/E13) -> 0.76359564 | F23: =IF(F13=0,"-",(F10+F11)/F13) -> 0.78469733 | G23: =IF(G13=0,"-",(G10+G11)/G13) -> 0.78971566 | H23: =IF(H13=0,"-",(H10+H11)/H13) -> 0.81764792 | I23: =IF(I13=0,"-",(I10+I11)/I13) -> 0.93798824 | J23: =IF(J13=0,"-",(J10+J11)/J13) -> 1.042153 | ... M23: =IF(M13=0,"-",(M10+M11)/M13) -> 1.2873508
A24: FedCo-held share of GovCo bonds | C24: =IF(C13=0,"-",C9/C13) -> 0.16842105 | D24: =IF(D13=0,"-",D9/D13) -> 0.18152574 | E24: =IF(E13=0,"-",E9/E13) -> 0.19168026 | F24: =IF(F13=0,"-",F9/F13) -> 0.20810211 | G24: =IF(G13=0,"-",G9/G13) -> 0.31938152 | H24: =IF(H13=0,"-",H9/H13) -> 0.27788721 | I24: =IF(I13=0,"-",I9/I13) -> 0.22627109 | J24: =IF(J13=0,"-",J9/J13) -> 0.17616044 | ... M24: =IF(M13=0,"-",M9/M13) -> 0.16034494
A25: Interest burden / tax revenue (debt service ratio) | C25: =IF(C16=0,"-",C18/C16) -> 0.058461538 | D25: =IF(D16=0,"-",D18/D16) -> 0.058461538 | E25: =IF(E16=0,"-",E18/E16) -> 0.066953846 | F25: =IF(F16=0,"-",F18/F16) -> 0.075446154 | G25: =IF(G16=0,"-",G18/G16) -> 0.084278154 | H25: =IF(H16=0,"-",H18/H16) -> 0.093449846 | I25: =IF(I16=0,"-",I18/I16) -> 0.10297482 | J25: =IF(J16=0,"-",J18/J16) -> 0.11286666 | ... M25: =IF(M16=0,"-",M18/M16) -> 0.14488744
A26: TIC-invisible / foreign private chain (reporting gap -- ClearCo novated / total repo) | B26: Rising = structural reporting gap widening | C26: =IF(GlobalBankCo!C4=0,"-",ClearCo!C4/GlobalBankCo!C4) -> 0.25 | D26: =IF(GlobalBankCo!D4=0,"-",ClearCo!D4/GlobalBankCo!D4) -> 0.3 | E26: =IF(GlobalBankCo!E4=0,"-",ClearCo!E4/GlobalBankCo!E4) -> 0.35 | F26: =IF(GlobalBankCo!F4=0,"-",ClearCo!F4/GlobalBankCo!F4) -> 0.4 | G26: =IF(GlobalBankCo!G4=0,"-",ClearCo!G4/GlobalBankCo!G4) -> 0.5 | H26: =IF(GlobalBankCo!H4=0,"-",ClearCo!H4/GlobalBankCo!H4) -> 0.55 | I26: =IF(GlobalBankCo!I4=0,"-",ClearCo!I4/GlobalBankCo!I4) -> 0.7 | J26: =IF(GlobalBankCo!J4=0,"-",ClearCo!J4/GlobalBankCo!J4) -> 0.72 | ... M26: =IF(GlobalBankCo!M4=0,"-",ClearCo!M4/GlobalBankCo!M4) -> 0.76

Sheet JapanCo
A1: JapanCo | Surplus Accumulator | JapCBCo = Central Bank | JapY = Domestic Currency
A2: Account / Line Item | B2: Notes / Source | C2: Y0 | D2: Y1 | E2: Y2 | F2: Y3 | G2: Y4 | H2: Y5 | I2: Y6 | J2: Y7 | K2: Y8 | L2: Y9 | M2: Y10+ Stress
A3: ASSETS
A4: JapCBCo official FX reserves ($B) | B4: JapCBCo = JapanCo central bank. Flat since Y0 peak. Routing gap = CA surplus not here. | C4: 650 | D4: =C4+ASSUMPTIONS!D15*ASSUMPTIONS!D14 -> 650.9 | E4: =D4+ASSUMPTIONS!E15*ASSUMPTIONS!E14 -> 652.4 | F4: =E4+ASSUMPTIONS!F15*ASSUMPTIONS!F14 -> 654.2 | G4: =F4+ASSUMPTIONS!G15*ASSUMPTIONS!G14 -> 656 | H4: =G4+ASSUMPTIONS!H15*ASSUMPTIONS!H14 -> 657.95 | I4: =H4+ASSUMPTIONS!I15*ASSUMPTIONS!I14 -> 660.47 | J4: =I4+ASSUMPTIONS!J15*ASSUMPTIONS!J14 -> 662.57 | K4: =J4+ASSUMPTIONS!K15*ASSUMPTIONS!K14 -> 664.67 | ... M4: =L4+ASSUMPTIONS!M15*ASSUMPTIONS!M14 -> 667.79
A5: Deposit at GlobalBankCo ($B) | B5: State rerouting channel. SLR entry point. SFC: = GlobalBankCo!liability_to_JapanCo. | C5: 40 | D5: =C5+ASSUMPTIONS!D12*(1-ASSUMPTIONS!D13)*ASSUMPTIONS!D14 -> 57.955 | E5: =D5+ASSUMPTIONS!E12*(1-ASSUMPTIONS!E13)*ASSUMPTIONS!E14 -> 91.205 | F5: =E5+ASSUMPTIONS!F12*(1-ASSUMPTIONS!F13)*ASSUMPTIONS!F14 -> 131.945 | G5: =F5+ASSUMPTIONS!G12*(1-ASSUMPTIONS!G13)*ASSUMPTIONS!G14 -> 168.401 | H5: =G5+ASSUMPTIONS!H12*(1-ASSUMPTIONS!H13)*ASSUMPTIONS!H14 -> 212.991 | I5: =H5+ASSUMPTIONS!I12*(1-ASSUMPTIONS!I13)*ASSUMPTIONS!I14 -> 287.835 | J5: =I5+ASSUMPTIONS!J12*(1-ASSUMPTIONS!J13)*ASSUMPTIONS!J14 -> 324.585 | K5: =J5+ASSUMPTIONS!K12*(1-ASSUMPTIONS!K13)*ASSUMPTIONS!K14 -> 398.835 | ... M5: =L5+ASSUMPTIONS!M12*(1-ASSUMPTIONS!M13)*ASSUMPTIONS!M14 -> 547.335
A6: Productive capital (domestic, JapY-denominated, $B equiv) | B6: High κ_paper domestic economy. Export-led accumulation model. JapY = JapanCo domestic currency. | C6: 800 | D6: =C6*1.04 -> 832 | E6: =D6*1.04 -> 865.28 | F6: =E6*1.04 -> 899.8912 | G6: =F6*1.04 -> 935.88685 | H6: =G6*1.04 -> 973.32232 | I6: =H6*1.04 -> 1012.2552 | J6: =I6*1.04 -> 1052.7454 | K6: =J6*1.04 -> 1094.8552 | ... M6: =L6*1.04 -> 1184.1954
A7: JapInv project claims ($B) | B7: Outward project lending (BRI analog). Claims on CommodityCo sovereigns. | C7: 50 | D7: =C7+ASSUMPTIONS!D19 -> 50 | E7: =D7+ASSUMPTIONS!E19 -> 50 | F7: =E7+ASSUMPTIONS!F19 -> 50 | G7: =F7+ASSUMPTIONS!G19 -> 50 | H7: =G7+ASSUMPTIONS!H19 -> 50 | I7: =H7+ASSUMPTIONS!I19 -> 50 | J7: =I7+ASSUMPTIONS!J19 -> 50 | K7: =J7+ASSUMPTIONS!K19 -> 50 | ... M7: =L7+ASSUMPTIONS!M19 -> 50
A8: TOTAL ASSETS | C8: =SUM(C4:C7) -> 1540 | D8: =SUM(D4:D7) -> 1590.855 | E8: =SUM(E4:E7) -> 1658.885 | F8: =SUM(F4:F7) -> 1736.0362 | G8: =SUM(G4:G7) -> 1810.2878 | H8: =SUM(H4:H7) -> 1894.2633 | I8: =SUM(I4:I7) -> 2010.5602 | J8: =SUM(J4:J7) -> 2089.9004 | ... M8: =SUM(M4:M7) -> 2449.3204
A10: LIABILITIES
A11: Domestic monetary base (JapY) | C11: 400 | D11: =C11*1.03 -> 412 | E11: =D11*1.03 -> 424.36 | F11: =E11*1.03 -> 437.0908 | G11: =F11*1.03 -> 450.20352 | H11: =G11*1.03 -> 463.70963 | I11: =H11*1.03 -> 477.62092 | J11: =I11*1.03 -> 491.94955 | K11: =J11*1.03 -> 506.70803 | ... M11: =L11*1.03 -> 537.56655
A12: Sterilization bonds ($B equiv) | B12: Cost of sterilization rises with reserve stock. Political economy constraint on JapY revaluation. | C12: 200 | D12: =C12*0.98 -> 196 | E12: =D12*0.98 -> 192.08 | F12: =E12*0.98 -> 188.2384 | G12: =F12*0.98 -> 184.47363 | H12: =G12*0.98 -> 180.78416 | I12: =H12*0.98 -> 177.16848 | J12: =I12*0.98 -> 173.62511 | K12: =J12*0.98 -> 170.1526 | ... M12: =L12*0.98 -> 163.41456
A13: TOTAL LIABILITIES | C13: =SUM(C11:C12) -> 600 | D13: =SUM(D11:D12) -> 608 | E13: =SUM(E11:E12) -> 616.44 | F13: =SUM(F11:F12) -> 625.3292 | G13: =SUM(G11:G12) -> 634.67716 | H13: =SUM(H11:H12) -> 644.49379 | I13: =SUM(I11:I12) -> 654.78939 | J13: =SUM(J11:J12) -> 665.57465 | ... M13: =SUM(M11:M12) -> 700.98111
A15: FRACTIONAL MEASURES
A16: Routing gap (cumul. CA surplus - JapCBCo reserve chg, $B) | B16: Real-world: $2.7T by Y9/2025 (Setser/IMF). Dollars not in official reserves. | C16: =0 -> 0 | D16: =C16+ASSUMPTIONS!D12*(1-ASSUMPTIONS!D13) -> 199.5 | E16: =D16+ASSUMPTIONS!E12*(1-ASSUMPTIONS!E13) -> 532 | F16: =E16+ASSUMPTIONS!F12*(1-ASSUMPTIONS!F13) -> 939.4 | G16: =F16+ASSUMPTIONS!G12*(1-ASSUMPTIONS!G13) -> 1243.2 | H16: =G16+ASSUMPTIONS!H12*(1-ASSUMPTIONS!H13) -> 1586.2 | I16: =H16+ASSUMPTIONS!I12*(1-ASSUMPTIONS!I13) -> 2002 | J16: =I16+ASSUMPTIONS!J12*(1-ASSUMPTIONS!J13) -> 2247 | K16: =J16+ASSUMPTIONS!K12*(1-ASSUMPTIONS!K13) -> 2742 | ... M16: =L16+ASSUMPTIONS!M12*(1-ASSUMPTIONS!M13) -> 3880.5
A17: Private channel open? | C17: =IF(ASSUMPTIONS!C20=1,"YES","NO") -> NO | D17: =IF(ASSUMPTIONS!D20=1,"YES","NO") -> NO | E17: =IF(ASSUMPTIONS!E20=1,"YES","NO") -> NO | F17: =IF(ASSUMPTIONS!F20=1,"YES","NO") -> NO | G17: =IF(ASSUMPTIONS!G20=1,"YES","NO") -> NO | H17: =IF(ASSUMPTIONS!H20=1,"YES","NO") -> NO | I17: =IF(ASSUMPTIONS!I20=1,"YES","NO") -> NO | J17: =IF(ASSUMPTIONS!J20=1,"YES","NO") -> NO | ... M17: =IF(ASSUMPTIONS!M20=1,"YES","NO") -> NO
A18: GlobalBankCo deposit share of routing gap | C18: =IF(C16=0,"-",C5/C16) -> - | D18: =IF(D16=0,"-",D5/D16) -> 0.29050125 | E18: =IF(E16=0,"-",E5/E16) -> 0.17143797 | F18: =IF(F16=0,"-",F5/F16) -> 0.14045667 | G18: =IF(G16=0,"-",G5/G16) -> 0.13545769 | H18: =IF(H16=0,"-",H5/H16) -> 0.13427752 | I18: =IF(I16=0,"-",I5/I16) -> 0.14377373 | J18: =IF(J16=0,"-",J5/J16) -> 0.1444526 | ... M18: =IF(M16=0,"-",M5/M16) -> 0.14104755

Sheet CommodityCo
A1: CommodityCo | Commodity Sovereign | Exogenous Shock Origin | Generic in Publication
A2: Account / Line Item | B2: Notes / Source | C2: Y0 | D2: Y1 | E2: Y2 | F2: Y3 | G2: Y4 | H2: Y5 | I2: Y6 | J2: Y7 | K2: Y8 | L2: Y9 | M2: Y10+ Stress
A3: ASSETS
A4: Deposit at GlobalBankCo ($B) | B4: Liquid dollar buffer. Withdrawal triggers DCR shock at GlobalBankCo (Path A). | C4: =ASSUMPTIONS!C22 -> 45 | D4: =C4*(1+ASSUMPTIONS!D23) -> 46.8 | E4: =D4*(1+ASSUMPTIONS!E23) -> 48.672 | F4: =E4*(1+ASSUMPTIONS!F23) -> 50.13216 | G4: =F4*(1+ASSUMPTIONS!G23) -> 47.12423 | H4: =G4*(1+ASSUMPTIONS!H23) -> 50.894169 | I4: =H4*(1+ASSUMPTIONS!I23) -> 53.947819 | J4: =I4*(1+ASSUMPTIONS!J23) -> 56.64521 | K4: =J4*(1+ASSUMPTIONS!K23) -> 59.47747 | ... M4: =L4*(1+ASSUMPTIONS!M23) -> 33.366861
A5: Direct Treasury holdings ($B) | B5: TIC-visible. Second liquidation target. Sale triggers yield spike (Path B). | C5: =ASSUMPTIONS!C24 -> 20 | D5: =C5*(1+ASSUMPTIONS!D25) -> 20.6 | E5: =D5*(1+ASSUMPTIONS!E25) -> 21.218 | F5: =E5*(1+ASSUMPTIONS!F25) -> 21.64236 | G5: =F5*(1+ASSUMPTIONS!G25) -> 20.776666 | H5: =G5*(1+ASSUMPTIONS!H25) -> 22.023266 | I5: =H5*(1+ASSUMPTIONS!I25) -> 23.124429 | J5: =I5*(1+ASSUMPTIONS!J25) -> 24.049406 | K5: =J5*(1+ASSUMPTIONS!K25) -> 25.011382 | ... M5: =L5*(1+ASSUMPTIONS!M25) -> 13.521153
A6: Commodity receivables ($B) | B6: Oil/gas/minerals. Price shock = exogenous trigger. Forces liquidation of dollar assets. | C6: =ASSUMPTIONS!C20 -> 60 | D6: =C6*(1+ASSUMPTIONS!D21) -> 54 | E6: =D6*(1+ASSUMPTIONS!E21) -> 56.7 | F6: =E6*(1+ASSUMPTIONS!F21) -> 62.37 | G6: =F6*(1+ASSUMPTIONS!G21) -> 34.3035 | H6: =G6*(1+ASSUMPTIONS!H21) -> 44.59455 | I6: =H6*(1+ASSUMPTIONS!I21) -> 53.51346 | J6: =I6*(1+ASSUMPTIONS!J21) -> 56.189133 | K6: =J6*(1+ASSUMPTIONS!K21) -> 61.808046 | ... M6: =L6*(1+ASSUMPTIONS!M21) -> 29.358822
A7: Sovereign wealth fund (equity/alts, $B) | C7: 100 | D7: =C7*1.04 -> 104 | E7: =D7*1.04 -> 108.16 | F7: =E7*1.04 -> 112.4864 | G7: =F7*1.04 -> 116.98586 | H7: =G7*1.04 -> 121.66529 | I7: =H7*1.04 -> 126.5319 | J7: =I7*1.04 -> 131.59318 | K7: =J7*1.04 -> 136.85691 | ... M7: =L7*1.04 -> 148.02443
A8: Gold reserves ($B) [Path C: outside banking chain] | C8: =ASSUMPTIONS!C26 -> 25 | D8: =C8*(1+ASSUMPTIONS!D27) -> 25 | E8: =D8*(1+ASSUMPTIONS!E27) -> 25 | F8: =E8*(1+ASSUMPTIONS!F27) -> 25 | G8: =F8*(1+ASSUMPTIONS!G27) -> 25 | H8: =G8*(1+ASSUMPTIONS!H27) -> 25 | I8: =H8*(1+ASSUMPTIONS!I27) -> 25 | J8: =I8*(1+ASSUMPTIONS!J27) -> 25 | K8: =J8*(1+ASSUMPTIONS!K27) -> 25 | L8: =K8*(1+ASSUMPTIONS!L27) -> 25 | M8: =L8*(1-ASSUMPTIONS!M28) -> 10
A9: Gold proceeds -> GBC deposit (stress yr, temp) [SFC: = GBC gold_temp_dep] | C9: 0 | D9: 0 | E9: 0 | F9: 0 | G9: 0 | H9: 0 | I9: 0 | J9: 0 | K9: 0 | L9: 0 | M9: =L8*ASSUMPTIONS!M28*ASSUMPTIONS!M29 -> 12
A10: TOTAL ASSETS
A12: LIABILITIES
A13: Sovereign debt (USD-denominated, $B) | C13: 15 | D13: =C13*1.04 -> 15.6 | E13: =D13*1.04 -> 16.224 | F13: =E13*1.04 -> 16.87296 | G13: =F13*1.04 -> 17.547878 | H13: =G13*1.04 -> 18.249794 | I13: =H13*1.04 -> 18.979785 | J13: =I13*1.04 -> 19.738977 | K13: =J13*1.04 -> 20.528536 | ... M13: =L13*1.04 -> 22.203664
A14: JapInv project obligations ($B) | B14: SFC: = JapanCo!JapInv_project_claims. Cross-actor identity. | C14: =JapanCo!C7 -> 50 | D14: =JapanCo!D7 -> 50 | E14: =JapanCo!E7 -> 50 | F14: =JapanCo!F7 -> 50 | G14: =JapanCo!G7 -> 50 | H14: =JapanCo!H7 -> 50 | I14: =JapanCo!I7 -> 50 | J14: =JapanCo!J7 -> 50 | ... M14: =JapanCo!M7 -> 50
A15: Short-term import financing ($B) | C15: 8 | D15: =C15*1.03 -> 8.24 | E15: =D15*1.03 -> 8.4872 | F15: =E15*1.03 -> 8.741816 | G15: =F15*1.03 -> 9.0040705 | H15: =G15*1.03 -> 9.2741926 | I15: =H15*1.03 -> 9.5524184 | J15: =I15*1.03 -> 9.8389909 | K15: =J15*1.03 -> 10.134161 | ... M15: =L15*1.03 -> 10.751331
A16: TOTAL LIABILITIES
A18: FRACTIONAL MEASURES
A19: CLC = L_liquid / (S_short + B_JapInv) | B19: Liquidity cliff. Below 1.2: forced liquidation. L_liquid = deposit + direct Treasury. S_short = USD sovereign debt. B_JapInv = JapInv project obligations due. | C19: =(C4+C5+C7*0.2+C8)/(C13+C14) -> 1.6923077 | D19: =(D4+D5+D7*0.2+D8)/(D13+D14) -> 1.7256098 | E19: =(E4+E5+E7*0.2+E8)/(E13+E14) -> 1.7595132 | F19: =(F4+F5+F7*0.2+F8)/(F13+F14) -> 1.783558 | G19: =(G4+G5+G7*0.2+G8)/(G13+G14) -> 1.7217131 | H19: =(H4+H5+H7*0.2+H8)/(H13+H14) -> 1.7912214 | I19: =(I4+I5+I7*0.2+I8)/(I13+I14) -> 1.8466081 | J19: =(J4+J5+J7*0.2+J8)/(J13+J14) -> 1.8929623 | ... M19: =(M4+M5+M7*0.2+M8)/(M13+M14) -> 1.1979018
A20: CLC hard constraint breach (< 1.0) -- forced liquidation is accounting consequence | C20: =IF(C19<1,"BREACH -- forced liquidation","OK") -> OK | D20: =IF(D19<1,"BREACH -- forced liquidation","OK") -> OK | E20: =IF(E19<1,"BREACH -- forced liquidation","OK") -> OK | F20: =IF(F19<1,"BREACH -- forced liquidation","OK") -> OK | G20: =IF(G19<1,"BREACH -- forced liquidation","OK") -> OK | H20: =IF(H19<1,"BREACH -- forced liquidation","OK") -> OK | I20: =IF(I19<1,"BREACH -- forced liquidation","OK") -> OK | J20: =IF(J19<1,"BREACH -- forced liquidation","OK") -> OK | ... M20: =IF(M19<1,"BREACH -- forced liquidation","OK") -> OK
A21: CLC (ex-gold): liquid w/o gold / obligations | C21: =(C4+C5+C7*0.2)/(C13+C14) -> 1.3076923 | D21: =(D4+D5+D7*0.2)/(D13+D14) -> 1.3445122 | E21: =(E4+E5+E7*0.2)/(E13+E14) -> 1.3820065 | F21: =(F4+F5+F7*0.2)/(F13+F14) -> 1.4097148 | G21: =(G4+G5+G7*0.2)/(G13+G14) -> 1.3516053 | H21: =(H4+H5+H7*0.2)/(H13+H14) -> 1.42492 | I21: =(I4+I5+I7*0.2)/(I13+I14) -> 1.4841831 | J21: =(J4+J5+J7*0.2)/(J13+J14) -> 1.5344827 | ... M21: =(M4+M5+M7*0.2)/(M13+M14) -> 1.0594047
A22: CLC early warning (< 1.2) -- buffer thinning, precautionary liquidation possible | C22: =IF(C19<1.2,IF(C19<1,"BREACH","WARNING"),"OK") -> OK | D22: =IF(D19<1.2,IF(D19<1,"BREACH","WARNING"),"OK") -> OK | E22: =IF(E19<1.2,IF(E19<1,"BREACH","WARNING"),"OK") -> OK | F22: =IF(F19<1.2,IF(F19<1,"BREACH","WARNING"),"OK") -> OK | G22: =IF(G19<1.2,IF(G19<1,"BREACH","WARNING"),"OK") -> OK | H22: =IF(H19<1.2,IF(H19<1,"BREACH","WARNING"),"OK") -> OK | I22: =IF(I19<1.2,IF(I19<1,"BREACH","WARNING"),"OK") -> OK | J22: =IF(J19<1.2,IF(J19<1,"BREACH","WARNING"),"OK") -> OK | ... M22: =IF(M19<1.2,IF(M19<1,"BREACH","WARNING"),"OK") -> WARNING

Sheet ClearCo
A1: ClearCo | Novation & Clearing Entity | Mirrors FICC CCP function
A2: Account / Line Item | B2: Notes | C2: Y0 | D2: Y1 | E2: Y2 | F2: Y3 | G2: Y4 | H2: Y5 | I2: Y6 | J2: Y7 | K2: Y8 | L2: Y9 | M2: Y10+
A3: ASSETS
A4: Novated GovCo bond collateral ($B) [SFC: = RepoCo off-balance novated Treasury r13] | B4: CCP holds novated bonds | C4: =RepoCo!C13 -> 25 | D4: =RepoCo!D13 -> 37.7265 | E4: =RepoCo!E13 -> 58.947805 | F4: =RepoCo!F13 -> 88.291119 | G4: =RepoCo!G13 -> 133.70977 | H4: =RepoCo!H13 -> 182.50356 | I4: =RepoCo!I13 -> 328.61551 | J4: =RepoCo!J13 -> 440.76765 | ... M4: =RepoCo!M13 -> 818.18494
A5: TOTAL ASSETS | C5: =SUM(C4:C4) -> 25 | D5: =SUM(D4:D4) -> 37.7265 | E5: =SUM(E4:E4) -> 58.947805 | F5: =SUM(F4:F4) -> 88.291119 | G5: =SUM(G4:G4) -> 133.70977 | H5: =SUM(H4:H4) -> 182.50356 | I5: =SUM(I4:I4) -> 328.61551 | J5: =SUM(J4:J4) -> 440.76765 | ... M5: =SUM(M4:M4) -> 818.18494
A7: LIABILITIES
A8: Novated repo obligation to RepoCo ($B) [SFC: = ClearCo assets -- CCP substituted as CCP] | B8: CCP owes back to RepoCo | C8: =C4 -> 25 | D8: =D4 -> 37.7265 | E8: =E4 -> 58.947805 | F8: =F4 -> 88.291119 | G8: =G4 -> 133.70977 | H8: =H4 -> 182.50356 | I8: =I4 -> 328.61551 | J8: =J4 -> 440.76765 | ... M8: =M4 -> 818.18494
A9: TOTAL LIABILITIES | C9: =SUM(C8:C8) -> 25 | D9: =SUM(D8:D8) -> 37.7265 | E9: =SUM(E8:E8) -> 58.947805 | F9: =SUM(F8:F8) -> 88.291119 | G9: =SUM(G8:G8) -> 133.70977 | H9: =SUM(H8:H8) -> 182.50356 | I9: =SUM(I8:I8) -> 328.61551 | J9: =SUM(J8:J8) -> 440.76765 | ... M9: =SUM(M8:M8) -> 818.18494
A11: NET POSITION (Assets - Liabilities) [Must = 0: ClearCo is pure pass-through] | C11: =C5-C9 -> 0 | D11: =D5-D9 -> 0 | E11: =E5-E9 -> 0 | F11: =F5-F9 -> 0 | G11: =G5-G9 -> 0 | H11: =H5-H9 -> 0 | I11: =I5-I9 -> 0 | J11: =J5-J9 -> 0 | ... M11: =M5-M9 -> 0
A13: ANALYTICAL NOTE
A14: Novation fraction (ASSUMPTIONS r39) -- % of repo book routed through ClearCo | C14: =ASSUMPTIONS!C39 -> 0.25 | D14: =ASSUMPTIONS!D39 -> 0.3 | E14: =ASSUMPTIONS!E39 -> 0.35 | F14: =ASSUMPTIONS!F39 -> 0.4 | G14: =ASSUMPTIONS!G39 -> 0.5 | H14: =ASSUMPTIONS!H39 -> 0.55 | I14: =ASSUMPTIONS!I39 -> 0.7 | J14: =ASSUMPTIONS!J39 -> 0.72 | ... M14: =ASSUMPTIONS!M39 -> 0.76
A15: ClearCo bonds / GlobalBankCo total repo book -- chain invisibility ratio | C15: =IF(GlobalBankCo!C4=0,"-",C4/GlobalBankCo!C4) -> 0.25 | D15: =IF(GlobalBankCo!D4=0,"-",D4/GlobalBankCo!D4) -> 0.3 | E15: =IF(GlobalBankCo!E4=0,"-",E4/GlobalBankCo!E4) -> 0.35 | F15: =IF(GlobalBankCo!F4=0,"-",F4/GlobalBankCo!F4) -> 0.4 | G15: =IF(GlobalBankCo!G4=0,"-",G4/GlobalBankCo!G4) -> 0.5 | H15: =IF(GlobalBankCo!H4=0,"-",H4/GlobalBankCo!H4) -> 0.55 | I15: =IF(GlobalBankCo!I4=0,"-",I4/GlobalBankCo!I4) -> 0.7 | J15: =IF(GlobalBankCo!J4=0,"-",J4/GlobalBankCo!J4) -> 0.72 | ... M15: =IF(GlobalBankCo!M4=0,"-",M4/GlobalBankCo!M4) -> 0.76
A16: NOTE: ClearCo holds the novated GovCo bonds as central counterparty. TIC reporting sees ClearCo (domestic CCP) not the original foreign funding chain. This is the structural reporting break -- not fraud, not concealment. The bond exists. The chain is severed at this step.

Sheet GlobalBankCo
A1: GlobalBankCo | International Bank | SLR Valve | Deposit-to-Repo Router
A2: Account / Line Item | B2: Notes / Source | C2: Y0 | D2: Y1 | E2: Y2 | F2: Y3 | G2: Y4 | H2: Y5 | I2: Y6 | J2: Y7 | K2: Y8 | L2: Y9 | M2: Y10+ Stress
A3: ASSETS
A4: Repo loans to RepoCo ($B) [SFC: = RepoCo!repo_payable_to_GlobalBankCo] | B4: Path B: SLR-constrained deposits routed to repo. SFC identity: this = RepoCo repo payable to GlobalBankCo. | C4: 100 | D4: =C4+(JapanCo!D5-JapanCo!C5)+(CommodityCo!D4-CommodityCo!C4)+C4*0.06 -> 125.755 | E4: =D4+(JapanCo!E5-JapanCo!D5)+(CommodityCo!E4-CommodityCo!D4)+D4*0.06 -> 168.4223 | F4: =E4+(JapanCo!F5-JapanCo!E5)+(CommodityCo!F4-CommodityCo!E4)+E4*0.06 -> 220.7278 | G4: =F4+(JapanCo!G5-JapanCo!F5)+(CommodityCo!G4-CommodityCo!F4)+F4*0.06 -> 267.41954 | H4: =G4+(JapanCo!H5-JapanCo!G5)+(CommodityCo!H4-CommodityCo!G4)+G4*0.06 -> 331.82465 | I4: =H4+(JapanCo!I5-JapanCo!H5)+(CommodityCo!I4-CommodityCo!H4)+H4*0.18 -> 469.45073 | J4: =I4+(JapanCo!J5-JapanCo!I5)+(CommodityCo!J4-CommodityCo!I4)+I4*0.22 -> 612.17729 | K4: =J4+(JapanCo!K5-JapanCo!J5)+(CommodityCo!K4-CommodityCo!J4)+J4*0.18 -> 799.45146 | L4: =K4+(JapanCo!L5-JapanCo!K5)+(CommodityCo!L4-CommodityCo!K4)+K4*0.12 -> 979.73518 | M4: =L4+(JapanCo!M5-JapanCo!L5)+(CommodityCo!M4-CommodityCo!L4)+L4*0.06 -> 1076.5591
A5: Gold-funded additional repo to RepoCo (stress yr) [SFC: = RepoCo!gold_repo] | C5: 0 | D5: 0 | E5: 0 | F5: 0 | G5: 0 | H5: 0 | I5: 0 | J5: 0 | K5: 0 | L5: 0 | M5: =CommodityCo!M9 -> 12
A6: Direct Treasury (Path A, HQLA, $B) | B6: Path A: when SLR not binding, deposits -> direct Treasury. TIC-visible. Stable demand. | C6: 60 | D6: =C6*1.03 -> 61.8 | E6: =D6*1.03 -> 63.654 | F6: =E6*1.03 -> 65.56362 | G6: =F6*1.03 -> 67.530529 | H6: =G6*1.03 -> 69.556444 | I6: =H6*1.03 -> 71.643138 | J6: =I6*1.03 -> 73.792432 | K6: =J6*1.03 -> 76.006205 | ... M6: =L6*1.03 -> 80.634983
A7: Other loans ($B) | C7: =ASSUMPTIONS!C31 -> 25 | D7: =C7*1.02 -> 25.5 | E7: =D7*1.02 -> 26.01 | F7: =E7*1.02 -> 26.5302 | G7: =F7*1.02 -> 27.060804 | H7: =G7*1.02 -> 27.60202 | I7: =H7*1.02 -> 28.15406 | J7: =I7*1.02 -> 28.717142 | K7: =J7*1.02 -> 29.291485 | ... M7: =L7*1.02 -> 30.47486
A8: Reserves at FedCo ($B) | B8: Count toward SLR denominator. Post-COVID reserve glut constrained SLR for major banks. | C8: 40 | D8: =C8*1.01 -> 40.4 | E8: =D8*1.01 -> 40.804 | F8: =E8*1.01 -> 41.21204 | G8: =F8*1.01 -> 41.62416 | H8: =G8*1.01 -> 42.040402 | I8: =H8*1.01 -> 42.460806 | J8: =I8*1.01 -> 42.885414 | K8: =J8*1.01 -> 43.314268 | ... M8: =L8*1.01 -> 44.184885
A9: TOTAL ASSETS | C9: =SUM(C4:C8) -> 225 | D9: =SUM(D4:D8) -> 253.455 | E9: =SUM(E4:E8) -> 298.8903 | F9: =SUM(F4:F8) -> 354.03366 | G9: =SUM(G4:G8) -> 403.63503 | H9: =SUM(H4:H8) -> 471.02351 | I9: =SUM(I4:I8) -> 611.70874 | J9: =SUM(J4:J8) -> 757.57227 | ... M9: =SUM(M4:M8) -> 1243.8539
A11: LIABILITIES
A12: Deposits from JapanCo ($B) [SFC: = JapanCo!deposit_at_GlobalBankCo] | B12: SFC identity enforced by formula. BIS LBS code G proxy (loans+deposits, inseparable -- structural BIS limitation). | C12: =JapanCo!C5 -> 40 | D12: =JapanCo!D5 -> 57.955 | E12: =JapanCo!E5 -> 91.205 | F12: =JapanCo!F5 -> 131.945 | G12: =JapanCo!G5 -> 168.401 | H12: =JapanCo!H5 -> 212.991 | I12: =JapanCo!I5 -> 287.835 | J12: =JapanCo!J5 -> 324.585 | ... M12: =JapanCo!M5 -> 547.335
A13: Deposits from CommodityCo ($B) [SFC: = CommodityCo!deposit_at_GlobalBankCo] | B13: Second sovereign deposit source. Withdrawal at stress = CLC breach trigger. | C13: =CommodityCo!C4 -> 45 | D13: =CommodityCo!D4 -> 46.8 | E13: =CommodityCo!E4 -> 48.672 | F13: =CommodityCo!F4 -> 50.13216 | G13: =CommodityCo!G4 -> 47.12423 | H13: =CommodityCo!H4 -> 50.894169 | I13: =CommodityCo!I4 -> 53.947819 | J13: =CommodityCo!J4 -> 56.64521 | ... M13: =CommodityCo!M4 -> 33.366861
A14: Gold proceeds temp deposit (stress yr) [SFC: = CommodityCo!gold_proceeds] | C14: 0 | D14: 0 | E14: 0 | F14: 0 | G14: 0 | H14: 0 | I14: 0 | J14: 0 | K14: 0 | L14: 0 | M14: =CommodityCo!M9 -> 12
A15: Wholesale funding ($B) | C15: 100 | D15: =C13*1.02 -> 45.9 | E15: =D13*1.02 -> 47.736 | F15: =E13*1.02 -> 49.64544 | G15: =F13*1.02 -> 51.134803 | H15: =G13*1.02 -> 48.066715 | I15: =H13*1.02 -> 51.912052 | J15: =I13*1.02 -> 55.026775 | K15: =J13*1.02 -> 57.778114 | ... M15: =L13*1.02 -> 61.88036
A16: Other liabilities ($B) | C16: 40 | D16: =C14*1.01 -> 0 | E16: =D14*1.01 -> 0 | F16: =E14*1.01 -> 0 | G16: =F14*1.01 -> 0 | H16: =G14*1.01 -> 0 | I16: =H14*1.01 -> 0 | J16: =I14*1.01 -> 0 | K16: =J14*1.01 -> 0 | ... M16: =L14*1.01 -> 0
A17: TOTAL LIABILITIES
A19: FRACTIONAL MEASURES
A20: DCR = (Dep_JapanCo + Dep_CommodityCo) / Repo_book | B20: Deposit Coverage Ratio. DCR < 1 = repo book exceeds sovereign deposit base. DCR decline signals withdrawal risk. Pressure gauge for Path A trigger. | C20: =IF(C4=0,"-",(C11+C12)/C4) -> 0.4 | D20: =IF(D4=0,"-",(D11+D12)/D4) -> 0.46085643 | E20: =IF(E4=0,"-",(E11+E12)/E4) -> 0.54152568 | F20: =IF(F4=0,"-",(F11+F12)/F4) -> 0.59777247 | G20: =IF(G4=0,"-",(G11+G12)/G4) -> 0.62972587 | H20: =IF(H4=0,"-",(H11+H12)/H4) -> 0.64187818 | I20: =IF(I4=0,"-",(I11+I12)/I4) -> 0.61313143 | J20: =IF(J4=0,"-",(J11+J12)/J4) -> 0.53021405 | ... M20: =IF(M4=0,"-",(M11+M12)/M4) -> 0.50841146
A21: SLR (simplified) = Tier1 / Total Exposure | B21: Simplified SLR. Tier1 ~8% of assets. Total exposure = total assets + off-BS items. Minimum 5% (US GSIBs). SLR reform Nov 2025 changes denominator. | C21: =C9*0.08/(C9*1.05) -> 0.076190476 | D21: =D9*0.08/(D9*1.05) -> 0.076190476 | E21: =E9*0.08/(E9*1.05) -> 0.076190476 | F21: =F9*0.08/(F9*1.05) -> 0.076190476 | G21: =G9*0.08/(G9*1.05) -> 0.076190476 | H21: =H9*0.08/(H9*1.05) -> 0.076190476 | I21: =I9*0.08/(I9*1.05) -> 0.076190476 | J21: =J9*0.08/(J9*1.05) -> 0.076190476 | ... M21: =M9*0.08/(M9*1.05) -> 0.076190476
A22: SLR binding? (< constraint threshold = YES) | C22: =IF(C21<ASSUMPTIONS!C34,"YES","NO") -> NO | D22: =IF(D21<ASSUMPTIONS!D34,"YES","NO") -> NO | E22: =IF(E21<ASSUMPTIONS!E34,"YES","NO") -> NO | F22: =IF(F21<ASSUMPTIONS!F34,"YES","NO") -> NO | G22: =IF(G21<ASSUMPTIONS!G34,"YES","NO") -> NO | H22: =IF(H21<ASSUMPTIONS!H34,"YES","NO") -> NO | I22: =IF(I21<ASSUMPTIONS!I34,"YES","NO") -> NO | J22: =IF(J21<ASSUMPTIONS!J34,"YES","NO") -> NO | ... M22: =IF(M21<ASSUMPTIONS!M34,"YES","NO") -> NO
A23: AUGMENTED COVERAGE RATIO (ACR): DCR + gold proceeds / Repo book -- TEMPORARY FALSE STABILIZATION signal. NOT baseline DCR. Rises in stress year before Path A/B fire. | C23: =IF(C4=0,"-",(C11+C12+C13)/C4) -> 0.85 | D23: =IF(D4=0,"-",(D11+D12+D13)/D4) -> 0.83300863 | E23: =IF(E4=0,"-",(E11+E12+E13)/E4) -> 0.83051354 | F23: =IF(F4=0,"-",(F11+F12+F13)/F4) -> 0.82489456 | G23: =IF(G4=0,"-",(G11+G12+G13)/G4) -> 0.80594422 | H23: =IF(H4=0,"-",(H11+H12+H13)/H4) -> 0.79525488 | I23: =IF(I4=0,"-",(I11+I12+I13)/I4) -> 0.72804832 | J23: =IF(J4=0,"-",(J11+J12+J13)/J4) -> 0.62274478 | ... M23: =IF(M4=0,"-",(M11+M12+M13)/M4) -> 0.53940545

Sheet RepoCo
A1: RepoCo | Repo Desk | FICC Member | TIC Chain Break Point
A2: Account / Line Item | B2: Notes / Source | C2: Y0 | D2: Y1 | E2: Y2 | F2: Y3 | G2: Y4 | H2: Y5 | I2: Y6 | J2: Y7 | K2: Y8 | L2: Y9 | M2: Y10+ Stress
A3: ASSETS (on balance sheet)
A4: Treasury collateral (pre-novation, on books, $B) | B4: Before FICC novation. Visible on RepoCo books and in TIC. | C4: =GlobalBankCo!C4*(1-ASSUMPTIONS!C39) -> 75 | D4: =GlobalBankCo!D4*(1-ASSUMPTIONS!D39) -> 88.0285 | E4: =GlobalBankCo!E4*(1-ASSUMPTIONS!E39) -> 109.4745 | F4: =GlobalBankCo!F4*(1-ASSUMPTIONS!F39) -> 132.43668 | G4: =GlobalBankCo!G4*(1-ASSUMPTIONS!G39) -> 133.70977 | H4: =GlobalBankCo!H4*(1-ASSUMPTIONS!H39) -> 149.32109 | I4: =GlobalBankCo!I4*(1-ASSUMPTIONS!I39) -> 140.83522 | J4: =GlobalBankCo!J4*(1-ASSUMPTIONS!J39) -> 171.40964 | ... M4: =GlobalBankCo!M4*(1-ASSUMPTIONS!M39) -> 258.37419
A5: Repo receivable from HedgeCo ($B) [SFC: = HedgeCo!repo_payable_to_RepoCo] | B5: Mirror: RepoCo lends cash to HedgeCo against Treasury collateral. | C5: =GlobalBankCo!C4 -> 100 | D5: =GlobalBankCo!D4 -> 125.755 | E5: =GlobalBankCo!E4 -> 168.4223 | F5: =GlobalBankCo!F4 -> 220.7278 | G5: =GlobalBankCo!G4 -> 267.41954 | H5: =GlobalBankCo!H4 -> 331.82465 | I5: =GlobalBankCo!I4 -> 469.45073 | J5: =GlobalBankCo!J4 -> 612.17729 | ... M5: =GlobalBankCo!M4 -> 1076.5591
A6: Gold-funded additional repo recv from GBC (stress yr) | C6: 0 | D6: 0 | E6: 0 | F6: 0 | G6: 0 | H6: 0 | I6: 0 | J6: 0 | K6: 0 | L6: 0 | M6: =GlobalBankCo!M5 -> 12
A7: TOTAL ASSETS (on balance sheet) | C7: =SUM(C4:C6) -> 175 | D7: =SUM(D4:D6) -> 213.7835 | E7: =SUM(E4:E6) -> 277.89679 | F7: =SUM(F4:F6) -> 353.16448 | G7: =SUM(G4:G6) -> 401.1293 | H7: =SUM(H4:H6) -> 481.14574 | I7: =SUM(I4:I6) -> 610.28595 | J7: =SUM(J4:J6) -> 783.58693 | ... M7: =SUM(M4:M6) -> 1346.9333
A9: LIABILITIES (on balance sheet)
A10: Repo payable to GlobalBankCo ($B) [SFC: = GlobalBankCo!repo_loans_to_RepoCo] | B10: SFC identity: must equal GlobalBankCo repo loans to RepoCo. | C10: =GlobalBankCo!C4 -> 100 | D10: =GlobalBankCo!D4 -> 125.755 | E10: =GlobalBankCo!E4 -> 168.4223 | F10: =GlobalBankCo!F4 -> 220.7278 | G10: =GlobalBankCo!G4 -> 267.41954 | H10: =GlobalBankCo!H4 -> 331.82465 | I10: =GlobalBankCo!I4 -> 469.45073 | J10: =GlobalBankCo!J4 -> 612.17729 | ... M10: =GlobalBankCo!M4 -> 1076.5591
A12: DERIVATIVE / OFF-BALANCE-SHEET (FICC novation -- TIC chain break)
A13: Treasury collateral (post-FICC novation, OFF books, $B) | B13: CRITICAL: After FICC novation, these Treasuries move to FICC CCP. TIC reporting stops here. Foreign funding origin invisible. This is the structural source of the $1.4T Barth-Beltran gap. | C13: =GlobalBankCo!C4*ASSUMPTIONS!C39 -> 25 | D13: =GlobalBankCo!D4*ASSUMPTIONS!D39 -> 37.7265 | E13: =GlobalBankCo!E4*ASSUMPTIONS!E39 -> 58.947805 | F13: =GlobalBankCo!F4*ASSUMPTIONS!F39 -> 88.291119 | G13: =GlobalBankCo!G4*ASSUMPTIONS!G39 -> 133.70977 | H13: =GlobalBankCo!H4*ASSUMPTIONS!H39 -> 182.50356 | I13: =GlobalBankCo!I4*ASSUMPTIONS!I39 -> 328.61551 | J13: =GlobalBankCo!J4*ASSUMPTIONS!J39 -> 440.76765 | ... M13: =GlobalBankCo!M4*ASSUMPTIONS!M39 -> 818.18494
A15: FRACTIONAL MEASURES
A16: CV = Repo gross notional / Treasury collateral (on-books) | B16: Collateral Velocity. Rising = same Treasury pledged multiple times. Each rehypothecation = one more link where TIC chain breaks. | C16: =IF(C4=0,"-",C5/C4) -> 1.3333333 | D16: =IF(D4=0,"-",D5/D4) -> 1.4285714 | E16: =IF(E4=0,"-",E5/E4) -> 1.5384615 | F16: =IF(F4=0,"-",F5/F4) -> 1.6666667 | G16: =IF(G4=0,"-",G5/G4) -> 2 | H16: =IF(H4=0,"-",H5/H4) -> 2.2222222 | I16: =IF(I4=0,"-",I5/I4) -> 3.3333333 | J16: =IF(J4=0,"-",J5/J4) -> 3.5714286 | ... M16: =IF(M4=0,"-",M5/M4) -> 4.1666667
A17: TIC gap at RepoCo = novated Treasury / total repo book | B17: Fraction of repo book where TIC chain is broken. Rising with FICC novation fraction assumption. | C17: =ASSUMPTIONS!C39 -> 0.25 | D17: =ASSUMPTIONS!D39 -> 0.3 | E17: =ASSUMPTIONS!E39 -> 0.35 | F17: =ASSUMPTIONS!F39 -> 0.4 | G17: =ASSUMPTIONS!G39 -> 0.5 | H17: =ASSUMPTIONS!H39 -> 0.55 | I17: =ASSUMPTIONS!I39 -> 0.7 | J17: =ASSUMPTIONS!J39 -> 0.72 | ... M17: =ASSUMPTIONS!M39 -> 0.76

Sheet HedgeCo
A1: HedgeCo | Basis Trade Vehicle | Cayman-Registered | 20-50x Leverage
A2: Account / Line Item | B2: Notes / Source | C2: Y0 | D2: Y1 | E2: Y2 | F2: Y3 | G2: Y4 | H2: Y5 | I2: Y6 | J2: Y7 | K2: Y8 | L2: Y9 | M2: Y10+ Stress
A3: ASSETS (on balance sheet)
A4: Long cash Treasury, repo-funded ($B) | B4: Long leg of basis trade. Funded by repo from RepoCo. NOT in TIC (Cayman + FICC novation breaks chain). | C4: =RepoCo!C5 -> 100 | D4: =RepoCo!D5 -> 125.755 | E4: =RepoCo!E5 -> 168.4223 | F4: =RepoCo!F5 -> 220.7278 | G4: =RepoCo!G5 -> 267.41954 | H4: =RepoCo!H5 -> 331.82465 | I4: =RepoCo!I5 -> 469.45073 | J4: =RepoCo!J5 -> 612.17729 | ... M4: =RepoCo!M5 -> 1076.5591
A5: Gold-funded additional cash Treasury (stress yr) [Path C recycled] | C5: 0 | D5: 0 | E5: 0 | F5: 0 | G5: 0 | H5: 0 | I5: 0 | J5: 0 | K5: 0 | L5: 0 | M5: =RepoCo!M6 -> 12
A6: Margin posted at exchange ($B) | B6: Small fraction of gross notional. Varies daily with mark-to-market. | C6: =C4*ASSUMPTIONS!C41*0.015 -> 1.95 | D6: =D4*ASSUMPTIONS!D41*0.015 -> 2.4522225 | E6: =E4*ASSUMPTIONS!E41*0.015 -> 3.2842348 | F6: =F4*ASSUMPTIONS!F41*0.015 -> 4.3041921 | G6: =G4*ASSUMPTIONS!G41*0.015 -> 5.214681 | H6: =H4*ASSUMPTIONS!H41*0.015 -> 6.4705806 | I6: =I4*ASSUMPTIONS!I41*0.015 -> 9.1542893 | J6: =J4*ASSUMPTIONS!J41*0.015 -> 11.937457 | ... M6: =M4*ASSUMPTIONS!M41*0.015 -> 20.992903
A7: TOTAL ASSETS (on balance sheet) | C7: =SUM(C4:C6) -> 101.95 | D7: =SUM(D4:D6) -> 128.20722 | E7: =SUM(E4:E6) -> 171.70653 | F7: =SUM(F4:F6) -> 225.03199 | G7: =SUM(G4:G6) -> 272.63422 | H7: =SUM(H4:H6) -> 338.29523 | I7: =SUM(I4:I6) -> 478.60502 | J7: =SUM(J4:J6) -> 624.11474 | ... M7: =SUM(M4:M6) -> 1109.552
A9: LIABILITIES (on balance sheet)
A10: Repo payable to RepoCo ($B) [SFC: = RepoCo!repo_receivable_from_HedgeCo] | B10: SFC identity: must equal RepoCo repo receivable from HedgeCo. If called by RepoCo, HedgeCo must sell cash Treasuries immediately. | C10: =RepoCo!C5 -> 100 | D10: =RepoCo!D5 -> 125.755 | E10: =RepoCo!E5 -> 168.4223 | F10: =RepoCo!F5 -> 220.7278 | G10: =RepoCo!G5 -> 267.41954 | H10: =RepoCo!H5 -> 331.82465 | I10: =RepoCo!I5 -> 469.45073 | J10: =RepoCo!J5 -> 612.17729 | ... M10: =RepoCo!M5 -> 1076.5591
A12: DERIVATIVES (gross notional -- NOT on standard balance sheet)
A13: Short Treasury futures (exchange, $B notional) | B13: Short leg of basis trade. CFTC TFF reports this. Real-world: $1,050B net short (Mar 2026, all tenors incl Ultra 10yr). NOT in TIC, NOT in bank balance sheets. | C13: =C4*ASSUMPTIONS!C41 -> 130 | D13: =D4*ASSUMPTIONS!D41 -> 163.4815 | E13: =E4*ASSUMPTIONS!E41 -> 218.94899 | F13: =F4*ASSUMPTIONS!F41 -> 286.94614 | G13: =G4*ASSUMPTIONS!G41 -> 347.6454 | H13: =H4*ASSUMPTIONS!H41 -> 431.37204 | I13: =I4*ASSUMPTIONS!I41 -> 610.28595 | J13: =J4*ASSUMPTIONS!J41 -> 795.83047 | ... M13: =M4*ASSUMPTIONS!M41 -> 1399.5269
A14: Gross basis trade exposure (cash + futures, $B) | B14: Total gross exposure. Barth-Beltran end-Y8 total: $1,850B. This is what FedCo must absorb in full unwind. | C14: =C4+C5+C13 -> 230 | D14: =D4+D5+D13 -> 289.2365 | E14: =E4+E5+E13 -> 387.37129 | F14: =F4+F5+F13 -> 507.67394 | G14: =G4+G5+G13 -> 615.06493 | H14: =H4+H5+H13 -> 763.19669 | I14: =I4+I5+I13 -> 1079.7367 | J14: =J4+J5+J13 -> 1408.0078 | ... M14: =M4+M5+M13 -> 2488.086
A16: FRACTIONAL MEASURES
A17: Leverage = Gross exposure / Equity | B17: Gross exposure / equity ($10B fixed). Starts ~23x (Y0). Rises as position scales against fixed equity base. Note: leverage narrative in description calibrated to Y0 entry level. | C17: =IF(ASSUMPTIONS!C43=0,"-",C14/ASSUMPTIONS!C43) -> 23 | D17: =IF(ASSUMPTIONS!C43=0,"-",D14/ASSUMPTIONS!C43) -> 28.92365 | E17: =IF(ASSUMPTIONS!C43=0,"-",E14/ASSUMPTIONS!C43) -> 38.737129 | F17: =IF(ASSUMPTIONS!C43=0,"-",F14/ASSUMPTIONS!C43) -> 50.767394 | G17: =IF(ASSUMPTIONS!C43=0,"-",G14/ASSUMPTIONS!C43) -> 61.506493 | H17: =IF(ASSUMPTIONS!C43=0,"-",H14/ASSUMPTIONS!C43) -> 76.319669 | I17: =IF(ASSUMPTIONS!C43=0,"-",I14/ASSUMPTIONS!C43) -> 107.97367 | J17: =IF(ASSUMPTIONS!C43=0,"-",J14/ASSUMPTIONS!C43) -> 140.80078 | K17: =IF(ASSUMPTIONS!C43=0,"-",K14/ASSUMPTIONS!C43) -> 183.87384 | L17: =IF(ASSUMPTIONS!C43=0,"-",L14/ASSUMPTIONS!C43) -> 225.33909 | M17: =IF(ASSUMPTIONS!C43=0,"-",M14/ASSUMPTIONS!C43) -> 248.8086
A18: BTAR numerator = Gross basis trade exposure ($B) | B18: Basis Trade Absorption Ratio numerator. Full unwind = this amount in Treasury selling into stressed market. BTAR = this / FedCo remaining headroom (see MEASURES sheet). | C18: =C14 -> 230 | D18: =D14 -> 289.2365 | E18: =E14 -> 387.37129 | F18: =F14 -> 507.67394 | G18: =G14 -> 615.06493 | H18: =H14 -> 763.19669 | I18: =I14 -> 1079.7367 | J18: =J14 -> 1408.0078 | ... M18: =M14 -> 2488.086
A20: STRESS SCENARIO (Y10+)
A21: Repo called (Path A): HedgeCo forced cash Treasury sale ($B) | B21: CommodityCo deposit withdrawal -> GlobalBankCo calls repo -> RepoCo calls HedgeCo. | C21: 0 | D21: 0 | E21: 0 | F21: 0 | G21: 0 | H21: 0 | I21: 0 | J21: 0 | K21: 0 | L21: 0 | M21: =-L4*0.3 -> -293.92055
A22: Margin breach (Path B): futures margin call ($B) | B22: Yield spike from CommodityCo Treasury sale -> futures P&L negative -> margin breach. | C22: 0 | D22: 0 | E22: 0 | F22: 0 | G22: 0 | H22: 0 | I22: 0 | J22: 0 | K22: 0 | L22: 0 | M22: =-M12*0.02 -> 0

Sheet FedCo
A1: FedCo | AmeriCo Central Bank | Absorber of Last Resort | Pressure Gauge
A2: Account / Line Item | B2: Notes / Source | C2: Y0 | D2: Y1 | E2: Y2 | F2: Y3 | G2: Y4 | H2: Y5 | I2: Y6 | J2: Y7 | K2: Y8 | L2: Y9 | M2: Y10+ Stress
A3: ASSETS
A4: Treasury holdings ($B) | B4: Real-world: Fed peaked $5.7T Treasuries Apr 2022. QT since. Y10+ stress: emergency absorption of HedgeCo unwind. | C4: =ASSUMPTIONS!C46 -> 64 | D4: =C4+ASSUMPTIONS!D47 -> 79 | E4: =D4+ASSUMPTIONS!E47 -> 94 | F4: =E4+ASSUMPTIONS!F47 -> 114 | G4: =F4+ASSUMPTIONS!G47 -> 194 | H4: =G4+ASSUMPTIONS!H47 -> 186 | I4: =H4+ASSUMPTIONS!I47 -> 166 | J4: =I4+ASSUMPTIONS!J47 -> 141 | K4: =J4+ASSUMPTIONS!K47 -> 126 | L4: =K4+ASSUMPTIONS!L47 -> 118 | M4: =L4+ASSUMPTIONS!M47+ASSUMPTIONS!M49 -> 163
A5: MBS holdings ($B) | C5: 80 | D5: =C5+ASSUMPTIONS!D44*0.55 -> 80 | E5: =D5+ASSUMPTIONS!E44*0.55 -> 80 | F5: =E5+ASSUMPTIONS!F44*0.55 -> 80 | G5: =F5+ASSUMPTIONS!G44*0.55 -> 80 | H5: =G5+ASSUMPTIONS!H44*0.55 -> 80 | I5: =H5+ASSUMPTIONS!I44*0.55 -> 80 | J5: =I5+ASSUMPTIONS!J44*0.55 -> 80 | K5: =J5+ASSUMPTIONS!K44*0.55 -> 80 | ... M5: =L5+ASSUMPTIONS!M44*0.55 -> 80
A6: TOTAL ASSETS (Balance Sheet, $B) | C6: =SUM(C4:C5) -> 144 | D6: =SUM(D4:D5) -> 159 | E6: =SUM(E4:E5) -> 174 | F6: =SUM(F4:F5) -> 194 | G6: =SUM(G4:G5) -> 274 | H6: =SUM(H4:H5) -> 266 | I6: =SUM(I4:I5) -> 246 | J6: =SUM(J4:J5) -> 221 | ... M6: =SUM(M4:M5) -> 243
A8: LIABILITIES
A9: Bank reserves ($B) | B9: Each dollar of Treasury purchase = one dollar of reserves. Stress absorption = reserve expansion. | C9: 200 | D9: =C9+ASSUMPTIONS!D44+ASSUMPTIONS!D46 -> 200 | E9: =D9+ASSUMPTIONS!E44+ASSUMPTIONS!E46 -> 200 | F9: =E9+ASSUMPTIONS!F44+ASSUMPTIONS!F46 -> 200 | G9: =F9+ASSUMPTIONS!G44+ASSUMPTIONS!G46 -> 200 | H9: =G9+ASSUMPTIONS!H44+ASSUMPTIONS!H46 -> 200 | I9: =H9+ASSUMPTIONS!I44+ASSUMPTIONS!I46 -> 200 | J9: =I9+ASSUMPTIONS!J44+ASSUMPTIONS!J46 -> 200 | K9: =J9+ASSUMPTIONS!K44+ASSUMPTIONS!K46 -> 200 | ... M9: =L9+ASSUMPTIONS!M44+ASSUMPTIONS!M46 -> 200
A10: Currency in circulation ($B) | C10: 150 | D10: =C10*1.04 -> 156 | E10: =D10*1.04 -> 162.24 | F10: =E10*1.04 -> 168.7296 | G10: =F10*1.04 -> 175.47878 | H10: =G10*1.04 -> 182.49794 | I10: =H10*1.04 -> 189.79785 | J10: =I10*1.04 -> 197.38977 | K10: =J10*1.04 -> 205.28536 | ... M10: =L10*1.04 -> 222.03664
A11: RRP (reverse repo, overnight, $B) | B11: Excess reserves parked at Fed. High RRP = system has more reserves than it wants. | C11: 0 | D11: 300 | E11: 300 | F11: 300 | G11: 200 | H11: 2500 | I11: 2000 | J11: 1500 | K11: 700 | L11: 300 | M11: 300
A13: FRACTIONAL MEASURES
A14: Fed BS / GDP | B14: Primary pressure gauge. At 38-40% = productive base constraint binding. Part II hard threshold. | C14: =C6/ASSUMPTIONS!C5 -> 0.51428571 | D14: =D6/ASSUMPTIONS!D5 -> 0.55400697 | E14: =E6/ASSUMPTIONS!E5 -> 0.59183673 | F14: =F6/ASSUMPTIONS!F5 -> 0.64238411 | G14: =G6/ASSUMPTIONS!G5 -> 0.95138889 | H14: =H6/ASSUMPTIONS!H5 -> 0.88666667 | I14: =I6/ASSUMPTIONS!I5 -> 0.7987013 | J14: =J6/ASSUMPTIONS!J5 -> 0.7015873 | ... M14: =M6/ASSUMPTIONS!M5 -> 0.81
A15: Remaining headroom ($B) = ceiling (40% GDP) - current BS | B15: BTAR denominator. Full basis trade unwind absorbs X% of this. | C15: =ASSUMPTIONS!C5*ASSUMPTIONS!C48-C6 -> 220 | D15: =ASSUMPTIONS!D5*ASSUMPTIONS!D48-D6 -> 214.1 | E15: =ASSUMPTIONS!E5*ASSUMPTIONS!E48-E6 -> 208.2 | F15: =ASSUMPTIONS!F5*ASSUMPTIONS!F48-F6 -> 198.6 | G15: =ASSUMPTIONS!G5*ASSUMPTIONS!G48-G6 -> 100.4 | H15: =ASSUMPTIONS!H5*ASSUMPTIONS!H48-H6 -> 124 | I15: =ASSUMPTIONS!I5*ASSUMPTIONS!I48-I6 -> 154.4 | J15: =ASSUMPTIONS!J5*ASSUMPTIONS!J48-J6 -> 188.5 | ... M15: =ASSUMPTIONS!M5*ASSUMPTIONS!M48-M6 -> 147
A17: STRESS (Y10+)
A18: Emergency Treasury purchase = HedgeCo forced sale ($B) | B18: SFC: FedCo buys what HedgeCo sells. The absorber IS the underlying. Balance sheet expands in the same asset under stress. | C18: 0 | D18: 0 | E18: 0 | F18: 0 | G18: 0 | H18: 0 | I18: 0 | J18: 0 | K18: 0 | L18: 0 | M18: =ASSUMPTIONS!M49 -> 45

Sheet SFC_CHECK
A1: SFC CHECK -- All cells must be GREEN. Red = model error in accounting identities.
A2: Account / Line Item | B2: Notes / Source | C2: Y0 | D2: Y1 | E2: Y2 | F2: Y3 | G2: Y4 | H2: Y5 | I2: Y6 | J2: Y7 | K2: Y8 | L2: Y9 | M2: Y10+ Stress
A3: SFC IDENTITY CHECKS -- difference = 0 means identity holds
A4: IDENTITY | B4: DESCRIPTION | C4: Y0 | D4: Y1 | E4: Y2 | F4: Y3 | G4: Y4 | H4: Y5 | I4: Y6 | J4: Y7 | K4: Y8 | L4: Y9 | M4: Y10+ Stress
A5: 1: JapanCo dep = GlobalBankCo liab to JapanCo | B5: JapanCo asset must equal GlobalBankCo liability. Core SFC constraint. | C5: =JapanCo!C5-(GlobalBankCo!C12) -> 0 | D5: =JapanCo!D5-(GlobalBankCo!D12) -> 0 | E5: =JapanCo!E5-(GlobalBankCo!E12) -> 0 | F5: =JapanCo!F5-(GlobalBankCo!F12) -> 0 | G5: =JapanCo!G5-(GlobalBankCo!G12) -> 0 | H5: =JapanCo!H5-(GlobalBankCo!H12) -> 0 | I5: =JapanCo!I5-(GlobalBankCo!I12) -> 0 | J5: =JapanCo!J5-(GlobalBankCo!J12) -> 0 | ... M5: =JapanCo!M5-(GlobalBankCo!M12) -> 0
A6: 2: CommodityCo dep = GlobalBankCo liab to CommodityCo | B6: CommodityCo asset must equal GlobalBankCo liability. | C6: =CommodityCo!C4-(GlobalBankCo!C13) -> 0 | D6: =CommodityCo!D4-(GlobalBankCo!D13) -> 0 | E6: =CommodityCo!E4-(GlobalBankCo!E13) -> 0 | F6: =CommodityCo!F4-(GlobalBankCo!F13) -> 0 | G6: =CommodityCo!G4-(GlobalBankCo!G13) -> 0 | H6: =CommodityCo!H4-(GlobalBankCo!H13) -> 0 | I6: =CommodityCo!I4-(GlobalBankCo!I13) -> 0 | J6: =CommodityCo!J4-(GlobalBankCo!J13) -> 0 | ... M6: =CommodityCo!M4-(GlobalBankCo!M13) -> 0
